[2024-10-10T01:16:38.028+0000] {task_context_logger.py:104} ERROR - Executor reports task instance <TaskInstance: train_ml_model_dag.train_model manual__2024-10-10T01:16:33.980566+00:00 [queued]> finished (failed) although the task says it's queued. (Info: None) Was the task killed externally?
